Workbook

Sheet Timeline
A1: MATRIX-AI / OSA 2.0 · Delivery timeline (Phase 1 to Gate 1, Jan 31, 2027 · Phase 2 to Gate 2, Mar 31, 2027)
A2: Default start | C2: 46335 | E2: Gantt start | G2: 46307 | I2: Blue = input. Start is typed (blue) or calculated (black): day after the latest predecessor's End, or same day as the task in 'Starts with'. End = Start + Duration − 1 (calendar days). Mark people with x. 'Waits for (resource)' = earlier task of the same person (one task at a time for each DE and BA).
P3: Functional lead | Q3: Business analyst · Sell-Out, BR VR, BR EASTER | R3: Business analyst · Promotions, Perfect Store | S3: Business analyst · SI-SO, Customer P&L, Market Share, Shipments, Inventory | T3: Business analyst · Sell-In, Sell-Through, Right Store, BR PVC | U3: Lead architect | V3: Data architect · WS-1, WS-2, WS-3 | W3: Data architect · WS-4, WS-5, WS-6 | X3: Solution architect | Y3: Data engineer · Python, WS-5 | Z3: Data engineer · Python, WS-5 | AA3: Data engineer · WS-1, WS-3 | AB3: Data engineer · WS-1, WS-3 | AC3: Data engineer · WS-2 | AD3: Data engineer · WS-2 | AE3: Data engineer · WS-4 | AF3: Data engineer · WS-6 | AG3: Data engineer · WS-6 | AH3: Data engineer · WS-2 BR | AI3: Data engineer · WS-2 SOCO | AJ3: FE (role to confirm) | AK3: FE (role to confirm) | AL3: FE (role to confirm) | AM3: FE (role to confirm) | AN3: FE (role to confirm) | AO3: =TEXT(AO4,"mmm yy") -> paź yy | AP3: =IF(MONTH(AP4)<>MONTH(AO4),TEXT(AP4,"mmm yy"),"") | AQ3: =IF(MONTH(AQ4)<>MONTH(AP4),TEXT(AQ4,"mmm yy"),"") | AR3: =IF(MONTH(AR4)<>MONTH(AQ4),TEXT(AR4,"mmm yy"),"") -> lis yy | AS3: =IF(MONTH(AS4)<>MONTH(AR4),TEXT(AS4,"mmm yy"),"") | AT3: =IF(MONTH(AT4)<>MONTH(AS4),TEXT(AT4,"mmm yy"),"") | AU3: =IF(MONTH(AU4)<>MONTH(AT4),TEXT(AU4,"mmm yy"),"") | AV3: =IF(MONTH(AV4)<>MONTH(AU4),TEXT(AV4,"mmm yy"),"") | AW3: =IF(MONTH(AW4)<>MONTH(AV4),TEXT(AW4,"mmm yy"),"") -> gru yy | ... CM3: =IF(MONTH(CM4)<>MONTH(CL4),TEXT(CM4,"mmm yy"),"")
A4: ID | B4: Lane | C4: Phase | D4: Workstream | E4: Maturity | F4: Phase / group | G4: Task | H4: Duration days | I4: Start | J4: End | K4: Type | L4: Depends on | M4: Waits for (resource) | N4: Other resource | O4: Days | P4: BA0 | Q4: BA1 | R4: BA2 | S4: BA3 | T4: BA4 | U4: DA0 | V4: DA1 | W4: DA2 | X4: SA1 | Y4: DE1 | Z4: DE2 | AA4: DE3 | AB4: DE4 | AC4: DE5 | AD4: DE6 | AE4: DE7 | AF4: DE8 | AG4: DE9 | AH4: DE10 | AI4: DE11 | AJ4: FE0 | AK4: FE1 | AL4: FE2 | AM4: FE3 | AN4: FE4 | AO4: =$G$2 -> 46307 | AP4: =AO4+7 -> 46314 | AQ4: =AP4+7 -> 46321 | AR4: =AQ4+7 -> 46328 | AS4: =AR4+7 -> 46335 | AT4: =AS4+7 -> 46342 | AU4: =AT4+7 -> 46349 | AV4: =AU4+7 -> 46356 | AW4: =AV4+7 -> 46363 | ... CM4: =CL4+7 -> 46657
A5: T-01 | B5: Mobilisation | C5: Phase 1 | G5: Blueprint workshop (4 days) | H5: 4 | I5: 46314 | J5: =IF(AND(ISNUMBER(I5),ISNUMBER(H5)),I5+H5-1,"") -> 46317 | K5: Task | N5: Architect, MDLZ | O5: =IF(AND(ISNUMBER(I5),ISNUMBER(J5)),J5-I5+1,"") -> 4 | AO5: =IF(AND(ISNUMBER($I5),OR($K5="Milestone",$K5="Deadline"),$I5>=AO$4,$I5<AO$4+7),IF($K5="Deadline","◇","◆"),"") | AP5: =IF(AND(ISNUMBER($I5),OR($K5="Milestone",$K5="Deadline"),$I5>=AP$4,$I5<AP$4+7),IF($K5="Deadline","◇","◆"),"") | AQ5: =IF(AND(ISNUMBER($I5),OR($K5="Milestone",$K5="Deadline"),$I5>=AQ$4,$I5<AQ$4+7),IF($K5="Deadline","◇","◆"),"") | AR5: =IF(AND(ISNUMBER($I5),OR($K5="Milestone",$K5="Deadline"),$I5>=AR$4,$I5<AR$4+7),IF($K5="Deadline","◇","◆"),"") | AS5: =IF(AND(ISNUMBER($I5),OR($K5="Milestone",$K5="Deadline"),$I5>=AS$4,$I5<AS$4+7),IF($K5="Deadline","◇","◆"),"") | AT5: =IF(AND(ISNUMBER($I5),OR($K5="Milestone",$K5="Deadline"),$I5>=AT$4,$I5<AT$4+7),IF($K5="Deadline","◇","◆"),"") | AU5: =IF(AND(ISNUMBER($I5),OR($K5="Milestone",$K5="Deadline"),$I5>=AU$4,$I5<AU$4+7),IF($K5="Deadline","◇","◆"),"") | AV5: =IF(AND(ISNUMBER($I5),OR($K5="Milestone",$K5="Deadline"),$I5>=AV$4,$I5<AV$4+7),IF($K5="Deadline","◇","◆"),"") | ... CM5: =IF(AND(ISNUMBER($I5),OR($K5="Milestone",$K5="Deadline"),$I5>=CM$4,$I5<CM$4+7),IF($K5="Deadline","◇","◆"),"")
A6: T-02 | B6: Mobilisation | C6: Phase 1 | G6: Environments, travel ready | I6: 46326 | J6: =I6 -> 46326 | K6: Milestone | N6: MDLZ platform | O6: =IF(AND(ISNUMBER(I6),ISNUMBER(J6)),J6-I6+1,"") -> 1 | AO6: =IF(AND(ISNUMBER($I6),OR($K6="Milestone",$K6="Deadline"),$I6>=AO$4,$I6<AO$4+7),IF($K6="Deadline","◇","◆"),"") | AP6: =IF(AND(ISNUMBER($I6),OR($K6="Milestone",$K6="Deadline"),$I6>=AP$4,$I6<AP$4+7),IF($K6="Deadline","◇","◆"),"") | AQ6: =IF(AND(ISNUMBER($I6),OR($K6="Milestone",$K6="Deadline"),$I6>=AQ$4,$I6<AQ$4+7),IF($K6="Deadline","◇","◆"),"") -> ◆ | AR6: =IF(AND(ISNUMBER($I6),OR($K6="Milestone",$K6="Deadline"),$I6>=AR$4,$I6<AR$4+7),IF($K6="Deadline","◇","◆"),"") | AS6: =IF(AND(ISNUMBER($I6),OR($K6="Milestone",$K6="Deadline"),$I6>=AS$4,$I6<AS$4+7),IF($K6="Deadline","◇","◆"),"") | AT6: =IF(AND(ISNUMBER($I6),OR($K6="Milestone",$K6="Deadline"),$I6>=AT$4,$I6<AT$4+7),IF($K6="Deadline","◇","◆"),"") | AU6: =IF(AND(ISNUMBER($I6),OR($K6="Milestone",$K6="Deadline"),$I6>=AU$4,$I6<AU$4+7),IF($K6="Deadline","◇","◆"),"") | AV6: =IF(AND(ISNUMBER($I6),OR($K6="Milestone",$K6="Deadline"),$I6>=AV$4,$I6<AV$4+7),IF($K6="Deadline","◇","◆"),"") | ... CM6: =IF(AND(ISNUMBER($I6),OR($K6="Milestone",$K6="Deadline"),$I6>=CM$4,$I6<CM$4+7),IF($K6="Deadline","◇","◆"),"")
A7: T-03 | B7: Mobilisation | C7: Phase 1 | G7: Named team starts | I7: 46335 | J7: =I7 -> 46335 | K7: Milestone | N7: All | O7: =IF(AND(ISNUMBER(I7),ISNUMBER(J7)),J7-I7+1,"") -> 1 | AO7: =IF(AND(ISNUMBER($I7),OR($K7="Milestone",$K7="Deadline"),$I7>=AO$4,$I7<AO$4+7),IF($K7="Deadline","◇","◆"),"") | AP7: =IF(AND(ISNUMBER($I7),OR($K7="Milestone",$K7="Deadline"),$I7>=AP$4,$I7<AP$4+7),IF($K7="Deadline","◇","◆"),"") | AQ7: =IF(AND(ISNUMBER($I7),OR($K7="Milestone",$K7="Deadline"),$I7>=AQ$4,$I7<AQ$4+7),IF($K7="Deadline","◇","◆"),"") | AR7: =IF(AND(ISNUMBER($I7),OR($K7="Milestone",$K7="Deadline"),$I7>=AR$4,$I7<AR$4+7),IF($K7="Deadline","◇","◆"),"") | AS7: =IF(AND(ISNUMBER($I7),OR($K7="Milestone",$K7="Deadline"),$I7>=AS$4,$I7<AS$4+7),IF($K7="Deadline","◇","◆"),"") -> ◆ | AT7: =IF(AND(ISNUMBER($I7),OR($K7="Milestone",$K7="Deadline"),$I7>=AT$4,$I7<AT$4+7),IF($K7="Deadline","◇","◆"),"") | AU7: =IF(AND(ISNUMBER($I7),OR($K7="Milestone",$K7="Deadline"),$I7>=AU$4,$I7<AU$4+7),IF($K7="Deadline","◇","◆"),"") | AV7: =IF(AND(ISNUMBER($I7),OR($K7="Milestone",$K7="Deadline"),$I7>=AV$4,$I7<AV$4+7),IF($K7="Deadline","◇","◆"),"") | ... CM7: =IF(AND(ISNUMBER($I7),OR($K7="Milestone",$K7="Deadline"),$I7>=CM$4,$I7<CM$4+7),IF($K7="Deadline","◇","◆"),"")
A8: T-04 | B8: Dependencies | C8: Phase 1 | G8: DP&E OTC (Sell-In) domain ready | I8: 46327 | J8: =I8 -> 46327 | K8: Milestone | N8: DP&E team | O8: =IF(AND(ISNUMBER(I8),ISNUMBER(J8)),J8-I8+1,"") -> 1 | AO8: =IF(AND(ISNUMBER($I8),OR($K8="Milestone",$K8="Deadline"),$I8>=AO$4,$I8<AO$4+7),IF($K8="Deadline","◇","◆"),"") | AP8: =IF(AND(ISNUMBER($I8),OR($K8="Milestone",$K8="Deadline"),$I8>=AP$4,$I8<AP$4+7),IF($K8="Deadline","◇","◆"),"") | AQ8: =IF(AND(ISNUMBER($I8),OR($K8="Milestone",$K8="Deadline"),$I8>=AQ$4,$I8<AQ$4+7),IF($K8="Deadline","◇","◆"),"") -> ◆ | AR8: =IF(AND(ISNUMBER($I8),OR($K8="Milestone",$K8="Deadline"),$I8>=AR$4,$I8<AR$4+7),IF($K8="Deadline","◇","◆"),"") | AS8: =IF(AND(ISNUMBER($I8),OR($K8="Milestone",$K8="Deadline"),$I8>=AS$4,$I8<AS$4+7),IF($K8="Deadline","◇","◆"),"") | AT8: =IF(AND(ISNUMBER($I8),OR($K8="Milestone",$K8="Deadline"),$I8>=AT$4,$I8<AT$4+7),IF($K8="Deadline","◇","◆"),"") | AU8: =IF(AND(ISNUMBER($I8),OR($K8="Milestone",$K8="Deadline"),$I8>=AU$4,$I8<AU$4+7),IF($K8="Deadline","◇","◆"),"") | AV8: =IF(AND(ISNUMBER($I8),OR($K8="Milestone",$K8="Deadline"),$I8>=AV$4,$I8<AV$4+7),IF($K8="Deadline","◇","◆"),"") | ... CM8: =IF(AND(ISNUMBER($I8),OR($K8="Milestone",$K8="Deadline"),$I8>=CM$4,$I8<CM$4+7),IF($K8="Deadline","◇","◆"),"")
A9: T-05 | B9: Dependencies | C9: Phase 1 | G9: DP&E EPOS (Sell-Out) domain ready | I9: 46327 | J9: =I9 -> 46327 | K9: Milestone | N9: DP&E team | O9: =IF(AND(ISNUMBER(I9),ISNUMBER(J9)),J9-I9+1,"") -> 1 | AO9: =IF(AND(ISNUMBER($I9),OR($K9="Milestone",$K9="Deadline"),$I9>=AO$4,$I9<AO$4+7),IF($K9="Deadline","◇","◆"),"") | AP9: =IF(AND(ISNUMBER($I9),OR($K9="Milestone",$K9="Deadline"),$I9>=AP$4,$I9<AP$4+7),IF($K9="Deadline","◇","◆"),"") | AQ9: =IF(AND(ISNUMBER($I9),OR($K9="Milestone",$K9="Deadline"),$I9>=AQ$4,$I9<AQ$4+7),IF($K9="Deadline","◇","◆"),"") -> ◆ | AR9: =IF(AND(ISNUMBER($I9),OR($K9="Milestone",$K9="Deadline"),$I9>=AR$4,$I9<AR$4+7),IF($K9="Deadline","◇","◆"),"") | AS9: =IF(AND(ISNUMBER($I9),OR($K9="Milestone",$K9="Deadline"),$I9>=AS$4,$I9<AS$4+7),IF($K9="Deadline","◇","◆"),"") | AT9: =IF(AND(ISNUMBER($I9),OR($K9="Milestone",$K9="Deadline"),$I9>=AT$4,$I9<AT$4+7),IF($K9="Deadline","◇","◆"),"") | AU9: =IF(AND(ISNUMBER($I9),OR($K9="Milestone",$K9="Deadline"),$I9>=AU$4,$I9<AU$4+7),IF($K9="Deadline","◇","◆"),"") | AV9: =IF(AND(ISNUMBER($I9),OR($K9="Milestone",$K9="Deadline"),$I9>=AV$4,$I9<AV$4+7),IF($K9="Deadline","◇","◆"),"") | ... CM9: =IF(AND(ISNUMBER($I9),OR($K9="Milestone",$K9="Deadline"),$I9>=CM$4,$I9<CM$4+7),IF($K9="Deadline","◇","◆"),"")
A10: T-06 | B10: Dependencies | C10: Phase 1 | G10: DP&E Distributor (Sell-Out) domain ready | I10: 46327 | J10: =I10 -> 46327 | K10: Milestone | N10: DP&E team | O10: =IF(AND(ISNUMBER(I10),ISNUMBER(J10)),J10-I10+1,"") -> 1 | AO10: =IF(AND(ISNUMBER($I10),OR($K10="Milestone",$K10="Deadline"),$I10>=AO$4,$I10<AO$4+7),IF($K10="Deadline","◇","◆"),"") | AP10: =IF(AND(ISNUMBER($I10),OR($K10="Milestone",$K10="Deadline"),$I10>=AP$4,$I10<AP$4+7),IF($K10="Deadline","◇","◆"),"") | AQ10: =IF(AND(ISNUMBER($I10),OR($K10="Milestone",$K10="Deadline"),$I10>=AQ$4,$I10<AQ$4+7),IF($K10="Deadline","◇","◆"),"") -> ◆ | AR10: =IF(AND(ISNUMBER($I10),OR($K10="Milestone",$K10="Deadline"),$I10>=AR$4,$I10<AR$4+7),IF($K10="Deadline","◇","◆"),"") | AS10: =IF(AND(ISNUMBER($I10),OR($K10="Milestone",$K10="Deadline"),$I10>=AS$4,$I10<AS$4+7),IF($K10="Deadline","◇","◆"),"") | AT10: =IF(AND(ISNUMBER($I10),OR($K10="Milestone",$K10="Deadline"),$I10>=AT$4,$I10<AT$4+7),IF($K10="Deadline","◇","◆"),"") | AU10: =IF(AND(ISNUMBER($I10),OR($K10="Milestone",$K10="Deadline"),$I10>=AU$4,$I10<AU$4+7),IF($K10="Deadline","◇","◆"),"") | AV10: =IF(AND(ISNUMBER($I10),OR($K10="Milestone",$K10="Deadline"),$I10>=AV$4,$I10<AV$4+7),IF($K10="Deadline","◇","◆"),"") | ... CM10: =IF(AND(ISNUMBER($I10),OR($K10="Milestone",$K10="Deadline"),$I10>=CM$4,$I10<CM$4+7),IF($K10="Deadline","◇","◆"),"")
A11: T-07 | B11: Dependencies | C11: Phase 1 | G11: DP&E LAFPA (Customer P&L) domain ready | I11: 46327 | J11: =I11 -> 46327 | K11: Milestone | N11: DP&E team | O11: =IF(AND(ISNUMBER(I11),ISNUMBER(J11)),J11-I11+1,"") -> 1 | AO11: =IF(AND(ISNUMBER($I11),OR($K11="Milestone",$K11="Deadline"),$I11>=AO$4,$I11<AO$4+7),IF($K11="Deadline","◇","◆"),"") | AP11: =IF(AND(ISNUMBER($I11),OR($K11="Milestone",$K11="Deadline"),$I11>=AP$4,$I11<AP$4+7),IF($K11="Deadline","◇","◆"),"") | AQ11: =IF(AND(ISNUMBER($I11),OR($K11="Milestone",$K11="Deadline"),$I11>=AQ$4,$I11<AQ$4+7),IF($K11="Deadline","◇","◆"),"") -> ◆ | AR11: =IF(AND(ISNUMBER($I11),OR($K11="Milestone",$K11="Deadline"),$I11>=AR$4,$I11<AR$4+7),IF($K11="Deadline","◇","◆"),"") | AS11: =IF(AND(ISNUMBER($I11),OR($K11="Milestone",$K11="Deadline"),$I11>=AS$4,$I11<AS$4+7),IF($K11="Deadline","◇","◆"),"") | AT11: =IF(AND(ISNUMBER($I11),OR($K11="Milestone",$K11="Deadline"),$I11>=AT$4,$I11<AT$4+7),IF($K11="Deadline","◇","◆"),"") | AU11: =IF(AND(ISNUMBER($I11),OR($K11="Milestone",$K11="Deadline"),$I11>=AU$4,$I11<AU$4+7),IF($K11="Deadline","◇","◆"),"") | AV11: =IF(AND(ISNUMBER($I11),OR($K11="Milestone",$K11="Deadline"),$I11>=AV$4,$I11<AV$4+7),IF($K11="Deadline","◇","◆"),"") | ... CM11: =IF(AND(ISNUMBER($I11),OR($K11="Milestone",$K11="Deadline"),$I11>=CM$4,$I11<CM$4+7),IF($K11="Deadline","◇","◆"),"")
A12: T-08 | B12: Dependencies | C12: Phase 1 | G12: Other DP&E products (Shipments), needed by | I12: 46342 | J12: =I12 -> 46342 | K12: Deadline | N12: DP&E team | O12: =IF(AND(ISNUMBER(I12),ISNUMBER(J12)),J12-I12+1,"") -> 1 | AO12: =IF(AND(ISNUMBER($I12),OR($K12="Milestone",$K12="Deadline"),$I12>=AO$4,$I12<AO$4+7),IF($K12="Deadline","◇","◆"),"") | AP12: =IF(AND(ISNUMBER($I12),OR($K12="Milestone",$K12="Deadline"),$I12>=AP$4,$I12<AP$4+7),IF($K12="Deadline","◇","◆"),"") | AQ12: =IF(AND(ISNUMBER($I12),OR($K12="Milestone",$K12="Deadline"),$I12>=AQ$4,$I12<AQ$4+7),IF($K12="Deadline","◇","◆"),"") | AR12: =IF(AND(ISNUMBER($I12),OR($K12="Milestone",$K12="Deadline"),$I12>=AR$4,$I12<AR$4+7),IF($K12="Deadline","◇","◆"),"") | AS12: =IF(AND(ISNUMBER($I12),OR($K12="Milestone",$K12="Deadline"),$I12>=AS$4,$I12<AS$4+7),IF($K12="Deadline","◇","◆"),"") | AT12: =IF(AND(ISNUMBER($I12),OR($K12="Milestone",$K12="Deadline"),$I12>=AT$4,$I12<AT$4+7),IF($K12="Deadline","◇","◆"),"") -> ◇ | AU12: =IF(AND(ISNUMBER($I12),OR($K12="Milestone",$K12="Deadline"),$I12>=AU$4,$I12<AU$4+7),IF($K12="Deadline","◇","◆"),"") | AV12: =IF(AND(ISNUMBER($I12),OR($K12="Milestone",$K12="Deadline"),$I12>=AV$4,$I12<AV$4+7),IF($K12="Deadline","◇","◆"),"") | ... CM12: =IF(AND(ISNUMBER($I12),OR($K12="Milestone",$K12="Deadline"),$I12>=CM$4,$I12<CM$4+7),IF($K12="Deadline","◇","◆"),"")
A13: T-09 | B13: Dependencies | C13: Phase 1 | G13: Snacksync database ready for analytics, needed by | I13: 46342 | J13: =I13 -> 46342 | K13: Deadline | N13: MDLZ, Snacksync | O13: =IF(AND(ISNUMBER(I13),ISNUMBER(J13)),J13-I13+1,"") -> 1 | AO13: =IF(AND(ISNUMBER($I13),OR($K13="Milestone",$K13="Deadline"),$I13>=AO$4,$I13<AO$4+7),IF($K13="Deadline","◇","◆"),"") | AP13: =IF(AND(ISNUMBER($I13),OR($K13="Milestone",$K13="Deadline"),$I13>=AP$4,$I13<AP$4+7),IF($K13="Deadline","◇","◆"),"") | AQ13: =IF(AND(ISNUMBER($I13),OR($K13="Milestone",$K13="Deadline"),$I13>=AQ$4,$I13<AQ$4+7),IF($K13="Deadline","◇","◆"),"") | AR13: =IF(AND(ISNUMBER($I13),OR($K13="Milestone",$K13="Deadline"),$I13>=AR$4,$I13<AR$4+7),IF($K13="Deadline","◇","◆"),"") | AS13: =IF(AND(ISNUMBER($I13),OR($K13="Milestone",$K13="Deadline"),$I13>=AS$4,$I13<AS$4+7),IF($K13="Deadline","◇","◆"),"") | AT13: =IF(AND(ISNUMBER($I13),OR($K13="Milestone",$K13="Deadline"),$I13>=AT$4,$I13<AT$4+7),IF($K13="Deadline","◇","◆"),"") -> ◇ | AU13: =IF(AND(ISNUMBER($I13),OR($K13="Milestone",$K13="Deadline"),$I13>=AU$4,$I13<AU$4+7),IF($K13="Deadline","◇","◆"),"") | AV13: =IF(AND(ISNUMBER($I13),OR($K13="Milestone",$K13="Deadline"),$I13>=AV$4,$I13<AV$4+7),IF($K13="Deadline","◇","◆"),"") | ... CM13: =IF(AND(ISNUMBER($I13),OR($K13="Milestone",$K13="Deadline"),$I13>=CM$4,$I13<CM$4+7),IF($K13="Deadline","◇","◆"),"")
A14: T-253 | B14: Dependencies | C14: Phase 1 | G14: Ataccama input and process definition (KPI inventory, DQ checks), needed by | I14: 46357 | J14: =I14 -> 46357 | K14: Deadline | N14: MDLZ Data Governance | O14: =IF(AND(ISNUMBER(I14),ISNUMBER(J14)),J14-I14+1,"") -> 1 | AO14: =IF(AND(ISNUMBER($I14),OR($K14="Milestone",$K14="Deadline"),$I14>=AO$4,$I14<AO$4+7),IF($K14="Deadline","◇","◆"),"") | AP14: =IF(AND(ISNUMBER($I14),OR($K14="Milestone",$K14="Deadline"),$I14>=AP$4,$I14<AP$4+7),IF($K14="Deadline","◇","◆"),"") | AQ14: =IF(AND(ISNUMBER($I14),OR($K14="Milestone",$K14="Deadline"),$I14>=AQ$4,$I14<AQ$4+7),IF($K14="Deadline","◇","◆"),"") | AR14: =IF(AND(ISNUMBER($I14),OR($K14="Milestone",$K14="Deadline"),$I14>=AR$4,$I14<AR$4+7),IF($K14="Deadline","◇","◆"),"") | AS14: =IF(AND(ISNUMBER($I14),OR($K14="Milestone",$K14="Deadline"),$I14>=AS$4,$I14<AS$4+7),IF($K14="Deadline","◇","◆"),"") | AT14: =IF(AND(ISNUMBER($I14),OR($K14="Milestone",$K14="Deadline"),$I14>=AT$4,$I14<AT$4+7),IF($K14="Deadline","◇","◆"),"") | AU14: =IF(AND(ISNUMBER($I14),OR($K14="Milestone",$K14="Deadline"),$I14>=AU$4,$I14<AU$4+7),IF($K14="Deadline","◇","◆"),"") | AV14: =IF(AND(ISNUMBER($I14),OR($K14="Milestone",$K14="Deadline"),$I14>=AV$4,$I14<AV$4+7),IF($K14="Deadline","◇","◆"),"") -> ◇ | ... CM14: =IF(AND(ISNUMBER($I14),OR($K14="Milestone",$K14="Deadline"),$I14>=CM$4,$I14<CM$4+7),IF($K14="Deadline","◇","◆"),"")
A15: T-263 | B15: Dependencies | C15: Phase 2 | G15: Perfect Store Source accessible BR | I15: 46327 | J15: =I15 -> 46327 | K15: Milestone | O15: =IF(AND(ISNUMBER(I15),ISNUMBER(J15)),J15-I15+1,"") -> 1 | AO15: =IF(AND(ISNUMBER($I15),OR($K15="Milestone",$K15="Deadline"),$I15>=AO$4,$I15<AO$4+7),IF($K15="Deadline","◇","◆"),"") | AP15: =IF(AND(ISNUMBER($I15),OR($K15="Milestone",$K15="Deadline"),$I15>=AP$4,$I15<AP$4+7),IF($K15="Deadline","◇","◆"),"") | AQ15: =IF(AND(ISNUMBER($I15),OR($K15="Milestone",$K15="Deadline"),$I15>=AQ$4,$I15<AQ$4+7),IF($K15="Deadline","◇","◆"),"") -> ◆ | AR15: =IF(AND(ISNUMBER($I15),OR($K15="Milestone",$K15="Deadline"),$I15>=AR$4,$I15<AR$4+7),IF($K15="Deadline","◇","◆"),"") | AS15: =IF(AND(ISNUMBER($I15),OR($K15="Milestone",$K15="Deadline"),$I15>=AS$4,$I15<AS$4+7),IF($K15="Deadline","◇","◆"),"") | AT15: =IF(AND(ISNUMBER($I15),OR($K15="Milestone",$K15="Deadline"),$I15>=AT$4,$I15<AT$4+7),IF($K15="Deadline","◇","◆"),"") | AU15: =IF(AND(ISNUMBER($I15),OR($K15="Milestone",$K15="Deadline"),$I15>=AU$4,$I15<AU$4+7),IF($K15="Deadline","◇","◆"),"") | AV15: =IF(AND(ISNUMBER($I15),OR($K15="Milestone",$K15="Deadline"),$I15>=AV$4,$I15<AV$4+7),IF($K15="Deadline","◇","◆"),"") | ... CM15: =IF(AND(ISNUMBER($I15),OR($K15="Milestone",$K15="Deadline"),$I15>=CM$4,$I15<CM$4+7),IF($K15="Deadline","◇","◆"),"")
A16: T-264 | B16: Dependencies | C16: Phase 2 | G16: Perfect Store Source accessible SOCO | I16: 46327 | J16: =I16 -> 46327 | K16: Milestone | O16: =IF(AND(ISNUMBER(I16),ISNUMBER(J16)),J16-I16+1,"") -> 1 | AO16: =IF(AND(ISNUMBER($I16),OR($K16="Milestone",$K16="Deadline"),$I16>=AO$4,$I16<AO$4+7),IF($K16="Deadline","◇","◆"),"") | AP16: =IF(AND(ISNUMBER($I16),OR($K16="Milestone",$K16="Deadline"),$I16>=AP$4,$I16<AP$4+7),IF($K16="Deadline","◇","◆"),"") | AQ16: =IF(AND(ISNUMBER($I16),OR($K16="Milestone",$K16="Deadline"),$I16>=AQ$4,$I16<AQ$4+7),IF($K16="Deadline","◇","◆"),"") -> ◆ | AR16: =IF(AND(ISNUMBER($I16),OR($K16="Milestone",$K16="Deadline"),$I16>=AR$4,$I16<AR$4+7),IF($K16="Deadline","◇","◆"),"") | AS16: =IF(AND(ISNUMBER($I16),OR($K16="Milestone",$K16="Deadline"),$I16>=AS$4,$I16<AS$4+7),IF($K16="Deadline","◇","◆"),"") | AT16: =IF(AND(ISNUMBER($I16),OR($K16="Milestone",$K16="Deadline"),$I16>=AT$4,$I16<AT$4+7),IF($K16="Deadline","◇","◆"),"") | AU16: =IF(AND(ISNUMBER($I16),OR($K16="Milestone",$K16="Deadline"),$I16>=AU$4,$I16<AU$4+7),IF($K16="Deadline","◇","◆"),"") | AV16: =IF(AND(ISNUMBER($I16),OR($K16="Milestone",$K16="Deadline"),$I16>=AV$4,$I16<AV$4+7),IF($K16="Deadline","◇","◆"),"") | ... CM16: =IF(AND(ISNUMBER($I16),OR($K16="Milestone",$K16="Deadline"),$I16>=CM$4,$I16<CM$4+7),IF($K16="Deadline","◇","◆"),"")
A17: T-265 | B17: Dependencies | C17: Phase 2 | G17: Perfect Store Source accessible WACAM | I17: 46327 | J17: =I17 -> 46327 | K17: Milestone | O17: =IF(AND(ISNUMBER(I17),ISNUMBER(J17)),J17-I17+1,"") -> 1 | AO17: =IF(AND(ISNUMBER($I17),OR($K17="Milestone",$K17="Deadline"),$I17>=AO$4,$I17<AO$4+7),IF($K17="Deadline","◇","◆"),"") | AP17: =IF(AND(ISNUMBER($I17),OR($K17="Milestone",$K17="Deadline"),$I17>=AP$4,$I17<AP$4+7),IF($K17="Deadline","◇","◆"),"") | AQ17: =IF(AND(ISNUMBER($I17),OR($K17="Milestone",$K17="Deadline"),$I17>=AQ$4,$I17<AQ$4+7),IF($K17="Deadline","◇","◆"),"") -> ◆ | AR17: =IF(AND(ISNUMBER($I17),OR($K17="Milestone",$K17="Deadline"),$I17>=AR$4,$I17<AR$4+7),IF($K17="Deadline","◇","◆"),"") | AS17: =IF(AND(ISNUMBER($I17),OR($K17="Milestone",$K17="Deadline"),$I17>=AS$4,$I17<AS$4+7),IF($K17="Deadline","◇","◆"),"") | AT17: =IF(AND(ISNUMBER($I17),OR($K17="Milestone",$K17="Deadline"),$I17>=AT$4,$I17<AT$4+7),IF($K17="Deadline","◇","◆"),"") | AU17: =IF(AND(ISNUMBER($I17),OR($K17="Milestone",$K17="Deadline"),$I17>=AU$4,$I17<AU$4+7),IF($K17="Deadline","◇","◆"),"") | AV17: =IF(AND(ISNUMBER($I17),OR($K17="Milestone",$K17="Deadline"),$I17>=AV$4,$I17<AV$4+7),IF($K17="Deadline","◇","◆"),"") | ... CM17: =IF(AND(ISNUMBER($I17),OR($K17="Milestone",$K17="Deadline"),$I17>=CM$4,$I17<CM$4+7),IF($K17="Deadline","◇","◆"),"")
A18: T-266 | B18: Dependencies | C18: Phase 2 | G18: Right Store Source accessible BR | I18: 46327 | J18: =I18 -> 46327 | K18: Milestone | O18: =IF(AND(ISNUMBER(I18),ISNUMBER(J18)),J18-I18+1,"") -> 1 | AO18: =IF(AND(ISNUMBER($I18),OR($K18="Milestone",$K18="Deadline"),$I18>=AO$4,$I18<AO$4+7),IF($K18="Deadline","◇","◆"),"") | AP18: =IF(AND(ISNUMBER($I18),OR($K18="Milestone",$K18="Deadline"),$I18>=AP$4,$I18<AP$4+7),IF($K18="Deadline","◇","◆"),"") | AQ18: =IF(AND(ISNUMBER($I18),OR($K18="Milestone",$K18="Deadline"),$I18>=AQ$4,$I18<AQ$4+7),IF($K18="Deadline","◇","◆"),"") -> ◆ | AR18: =IF(AND(ISNUMBER($I18),OR($K18="Milestone",$K18="Deadline"),$I18>=AR$4,$I18<AR$4+7),IF($K18="Deadline","◇","◆"),"") | AS18: =IF(AND(ISNUMBER($I18),OR($K18="Milestone",$K18="Deadline"),$I18>=AS$4,$I18<AS$4+7),IF($K18="Deadline","◇","◆"),"") | AT18: =IF(AND(ISNUMBER($I18),OR($K18="Milestone",$K18="Deadline"),$I18>=AT$4,$I18<AT$4+7),IF($K18="Deadline","◇","◆"),"") | AU18: =IF(AND(ISNUMBER($I18),OR($K18="Milestone",$K18="Deadline"),$I18>=AU$4,$I18<AU$4+7),IF($K18="Deadline","◇","◆"),"") | AV18: =IF(AND(ISNUMBER($I18),OR($K18="Milestone",$K18="Deadline"),$I18>=AV$4,$I18<AV$4+7),IF($K18="Deadline","◇","◆"),"") | ... CM18: =IF(AND(ISNUMBER($I18),OR($K18="Milestone",$K18="Deadline"),$I18>=CM$4,$I18<CM$4+7),IF($K18="Deadline","◇","◆"),"")
A19: T-267 | B19: Dependencies | C19: Phase 2 | G19: Right Store Source accessible SOCO | I19: 46327 | J19: =I19 -> 46327 | K19: Milestone | O19: =IF(AND(ISNUMBER(I19),ISNUMBER(J19)),J19-I19+1,"") -> 1 | AO19: =IF(AND(ISNUMBER($I19),OR($K19="Milestone",$K19="Deadline"),$I19>=AO$4,$I19<AO$4+7),IF($K19="Deadline","◇","◆"),"") | AP19: =IF(AND(ISNUMBER($I19),OR($K19="Milestone",$K19="Deadline"),$I19>=AP$4,$I19<AP$4+7),IF($K19="Deadline","◇","◆"),"") | AQ19: =IF(AND(ISNUMBER($I19),OR($K19="Milestone",$K19="Deadline"),$I19>=AQ$4,$I19<AQ$4+7),IF($K19="Deadline","◇","◆"),"") -> ◆ | AR19: =IF(AND(ISNUMBER($I19),OR($K19="Milestone",$K19="Deadline"),$I19>=AR$4,$I19<AR$4+7),IF($K19="Deadline","◇","◆"),"") | AS19: =IF(AND(ISNUMBER($I19),OR($K19="Milestone",$K19="Deadline"),$I19>=AS$4,$I19<AS$4+7),IF($K19="Deadline","◇","◆"),"") | AT19: =IF(AND(ISNUMBER($I19),OR($K19="Milestone",$K19="Deadline"),$I19>=AT$4,$I19<AT$4+7),IF($K19="Deadline","◇","◆"),"") | AU19: =IF(AND(ISNUMBER($I19),OR($K19="Milestone",$K19="Deadline"),$I19>=AU$4,$I19<AU$4+7),IF($K19="Deadline","◇","◆"),"") | AV19: =IF(AND(ISNUMBER($I19),OR($K19="Milestone",$K19="Deadline"),$I19>=AV$4,$I19<AV$4+7),IF($K19="Deadline","◇","◆"),"") | ... CM19: =IF(AND(ISNUMBER($I19),OR($K19="Milestone",$K19="Deadline"),$I19>=CM$4,$I19<CM$4+7),IF($K19="Deadline","◇","◆"),"")
A20: T-268 | B20: Dependencies | C20: Phase 2 | G20: Right Store Source accessible WACAM | I20: 46327 | J20: =I20 -> 46327 | K20: Milestone | O20: =IF(AND(ISNUMBER(I20),ISNUMBER(J20)),J20-I20+1,"") -> 1 | AO20: =IF(AND(ISNUMBER($I20),OR($K20="Milestone",$K20="Deadline"),$I20>=AO$4,$I20<AO$4+7),IF($K20="Deadline","◇","◆"),"") | AP20: =IF(AND(ISNUMBER($I20),OR($K20="Milestone",$K20="Deadline"),$I20>=AP$4,$I20<AP$4+7),IF($K20="Deadline","◇","◆"),"") | AQ20: =IF(AND(ISNUMBER($I20),OR($K20="Milestone",$K20="Deadline"),$I20>=AQ$4,$I20<AQ$4+7),IF($K20="Deadline","◇","◆"),"") -> ◆ | AR20: =IF(AND(ISNUMBER($I20),OR($K20="Milestone",$K20="Deadline"),$I20>=AR$4,$I20<AR$4+7),IF($K20="Deadline","◇","◆"),"") | AS20: =IF(AND(ISNUMBER($I20),OR($K20="Milestone",$K20="Deadline"),$I20>=AS$4,$I20<AS$4+7),IF($K20="Deadline","◇","◆"),"") | AT20: =IF(AND(ISNUMBER($I20),OR($K20="Milestone",$K20="Deadline"),$I20>=AT$4,$I20<AT$4+7),IF($K20="Deadline","◇","◆"),"") | AU20: =IF(AND(ISNUMBER($I20),OR($K20="Milestone",$K20="Deadline"),$I20>=AU$4,$I20<AU$4+7),IF($K20="Deadline","◇","◆"),"") | AV20: =IF(AND(ISNUMBER($I20),OR($K20="Milestone",$K20="Deadline"),$I20>=AV$4,$I20<AV$4+7),IF($K20="Deadline","◇","◆"),"") | ... CM20: =IF(AND(ISNUMBER($I20),OR($K20="Milestone",$K20="Deadline"),$I20>=CM$4,$I20<CM$4+7),IF($K20="Deadline","◇","◆"),"")
A21: T-269 | B21: Dependencies | C21: Phase 2 | G21: Market share source accessible MX | I21: 46327 | J21: =I21 -> 46327 | K21: Milestone | O21: =IF(AND(ISNUMBER(I21),ISNUMBER(J21)),J21-I21+1,"") -> 1 | AO21: =IF(AND(ISNUMBER($I21),OR($K21="Milestone",$K21="Deadline"),$I21>=AO$4,$I21<AO$4+7),IF($K21="Deadline","◇","◆"),"") | AP21: =IF(AND(ISNUMBER($I21),OR($K21="Milestone",$K21="Deadline"),$I21>=AP$4,$I21<AP$4+7),IF($K21="Deadline","◇","◆"),"") | AQ21: =IF(AND(ISNUMBER($I21),OR($K21="Milestone",$K21="Deadline"),$I21>=AQ$4,$I21<AQ$4+7),IF($K21="Deadline","◇","◆"),"") -> ◆ | AR21: =IF(AND(ISNUMBER($I21),OR($K21="Milestone",$K21="Deadline"),$I21>=AR$4,$I21<AR$4+7),IF($K21="Deadline","◇","◆"),"") | AS21: =IF(AND(ISNUMBER($I21),OR($K21="Milestone",$K21="Deadline"),$I21>=AS$4,$I21<AS$4+7),IF($K21="Deadline","◇","◆"),"") | AT21: =IF(AND(ISNUMBER($I21),OR($K21="Milestone",$K21="Deadline"),$I21>=AT$4,$I21<AT$4+7),IF($K21="Deadline","◇","◆"),"") | AU21: =IF(AND(ISNUMBER($I21),OR($K21="Milestone",$K21="Deadline"),$I21>=AU$4,$I21<AU$4+7),IF($K21="Deadline","◇","◆"),"") | AV21: =IF(AND(ISNUMBER($I21),OR($K21="Milestone",$K21="Deadline"),$I21>=AV$4,$I21<AV$4+7),IF($K21="Deadline","◇","◆"),"") | ... CM21: =IF(AND(ISNUMBER($I21),OR($K21="Milestone",$K21="Deadline"),$I21>=CM$4,$I21<CM$4+7),IF($K21="Deadline","◇","◆"),"")
A22: T-270 | B22: Dependencies | C22: Phase 2 | G22: Market share source accessible WACAM | I22: 46327 | J22: =I22 -> 46327 | K22: Milestone | O22: =IF(AND(ISNUMBER(I22),ISNUMBER(J22)),J22-I22+1,"") -> 1 | AO22: =IF(AND(ISNUMBER($I22),OR($K22="Milestone",$K22="Deadline"),$I22>=AO$4,$I22<AO$4+7),IF($K22="Deadline","◇","◆"),"") | AP22: =IF(AND(ISNUMBER($I22),OR($K22="Milestone",$K22="Deadline"),$I22>=AP$4,$I22<AP$4+7),IF($K22="Deadline","◇","◆"),"") | AQ22: =IF(AND(ISNUMBER($I22),OR($K22="Milestone",$K22="Deadline"),$I22>=AQ$4,$I22<AQ$4+7),IF($K22="Deadline","◇","◆"),"") -> ◆ | AR22: =IF(AND(ISNUMBER($I22),OR($K22="Milestone",$K22="Deadline"),$I22>=AR$4,$I22<AR$4+7),IF($K22="Deadline","◇","◆"),"") | AS22: =IF(AND(ISNUMBER($I22),OR($K22="Milestone",$K22="Deadline"),$I22>=AS$4,$I22<AS$4+7),IF($K22="Deadline","◇","◆"),"") | AT22: =IF(AND(ISNUMBER($I22),OR($K22="Milestone",$K22="Deadline"),$I22>=AT$4,$I22<AT$4+7),IF($K22="Deadline","◇","◆"),"") | AU22: =IF(AND(ISNUMBER($I22),OR($K22="Milestone",$K22="Deadline"),$I22>=AU$4,$I22<AU$4+7),IF($K22="Deadline","◇","◆"),"") | AV22: =IF(AND(ISNUMBER($I22),OR($K22="Milestone",$K22="Deadline"),$I22>=AV$4,$I22<AV$4+7),IF($K22="Deadline","◇","◆"),"") | ... CM22: =IF(AND(ISNUMBER($I22),OR($K22="Milestone",$K22="Deadline"),$I22>=CM$4,$I22<CM$4+7),IF($K22="Deadline","◇","◆"),"")
A23: T-271 | B23: Dependencies | C23: Phase 2 | G23: Market share source accessible BR | I23: 46327 | J23: =I23 -> 46327 | K23: Milestone | O23: =IF(AND(ISNUMBER(I23),ISNUMBER(J23)),J23-I23+1,"") -> 1 | AO23: =IF(AND(ISNUMBER($I23),OR($K23="Milestone",$K23="Deadline"),$I23>=AO$4,$I23<AO$4+7),IF($K23="Deadline","◇","◆"),"") | AP23: =IF(AND(ISNUMBER($I23),OR($K23="Milestone",$K23="Deadline"),$I23>=AP$4,$I23<AP$4+7),IF($K23="Deadline","◇","◆"),"") | AQ23: =IF(AND(ISNUMBER($I23),OR($K23="Milestone",$K23="Deadline"),$I23>=AQ$4,$I23<AQ$4+7),IF($K23="Deadline","◇","◆"),"") -> ◆ | AR23: =IF(AND(ISNUMBER($I23),OR($K23="Milestone",$K23="Deadline"),$I23>=AR$4,$I23<AR$4+7),IF($K23="Deadline","◇","◆"),"") | AS23: =IF(AND(ISNUMBER($I23),OR($K23="Milestone",$K23="Deadline"),$I23>=AS$4,$I23<AS$4+7),IF($K23="Deadline","◇","◆"),"") | AT23: =IF(AND(ISNUMBER($I23),OR($K23="Milestone",$K23="Deadline"),$I23>=AT$4,$I23<AT$4+7),IF($K23="Deadline","◇","◆"),"") | AU23: =IF(AND(ISNUMBER($I23),OR($K23="Milestone",$K23="Deadline"),$I23>=AU$4,$I23<AU$4+7),IF($K23="Deadline","◇","◆"),"") | AV23: =IF(AND(ISNUMBER($I23),OR($K23="Milestone",$K23="Deadline"),$I23>=AV$4,$I23<AV$4+7),IF($K23="Deadline","◇","◆"),"") | ... CM23: =IF(AND(ISNUMBER($I23),OR($K23="Milestone",$K23="Deadline"),$I23>=CM$4,$I23<CM$4+7),IF($K23="Deadline","◇","◆"),"")
A24: T-272 | B24: Dependencies | C24: Phase 2 | G24: Market share source accessible SOCO | I24: 46327 | J24: =I24 -> 46327 | K24: Milestone | O24: =IF(AND(ISNUMBER(I24),ISNUMBER(J24)),J24-I24+1,"") -> 1 | AO24: =IF(AND(ISNUMBER($I24),OR($K24="Milestone",$K24="Deadline"),$I24>=AO$4,$I24<AO$4+7),IF($K24="Deadline","◇","◆"),"") | AP24: =IF(AND(ISNUMBER($I24),OR($K24="Milestone",$K24="Deadline"),$I24>=AP$4,$I24<AP$4+7),IF($K24="Deadline","◇","◆"),"") | AQ24: =IF(AND(ISNUMBER($I24),OR($K24="Milestone",$K24="Deadline"),$I24>=AQ$4,$I24<AQ$4+7),IF($K24="Deadline","◇","◆"),"") -> ◆ | AR24: =IF(AND(ISNUMBER($I24),OR($K24="Milestone",$K24="Deadline"),$I24>=AR$4,$I24<AR$4+7),IF($K24="Deadline","◇","◆"),"") | AS24: =IF(AND(ISNUMBER($I24),OR($K24="Milestone",$K24="Deadline"),$I24>=AS$4,$I24<AS$4+7),IF($K24="Deadline","◇","◆"),"") | AT24: =IF(AND(ISNUMBER($I24),OR($K24="Milestone",$K24="Deadline"),$I24>=AT$4,$I24<AT$4+7),IF($K24="Deadline","◇","◆"),"") | AU24: =IF(AND(ISNUMBER($I24),OR($K24="Milestone",$K24="Deadline"),$I24>=AU$4,$I24<AU$4+7),IF($K24="Deadline","◇","◆"),"") | AV24: =IF(AND(ISNUMBER($I24),OR($K24="Milestone",$K24="Deadline"),$I24>=AV$4,$I24<AV$4+7),IF($K24="Deadline","◇","◆"),"") | ... CM24: =IF(AND(ISNUMBER($I24),OR($K24="Milestone",$K24="Deadline"),$I24>=CM$4,$I24<CM$4+7),IF($K24="Deadline","◇","◆"),"")
A25: T-279 | B25: Dependencies | C25: Phase 2 | G25: PIF ready for ingestion | I25: 46327 | J25: =I25 -> 46327 | K25: Milestone | O25: =IF(AND(ISNUMBER(I25),ISNUMBER(J25)),J25-I25+1,"") -> 1 | AO25: =IF(AND(ISNUMBER($I25),OR($K25="Milestone",$K25="Deadline"),$I25>=AO$4,$I25<AO$4+7),IF($K25="Deadline","◇","◆"),"") | AP25: =IF(AND(ISNUMBER($I25),OR($K25="Milestone",$K25="Deadline"),$I25>=AP$4,$I25<AP$4+7),IF($K25="Deadline","◇","◆"),"") | AQ25: =IF(AND(ISNUMBER($I25),OR($K25="Milestone",$K25="Deadline"),$I25>=AQ$4,$I25<AQ$4+7),IF($K25="Deadline","◇","◆"),"") -> ◆ | AR25: =IF(AND(ISNUMBER($I25),OR($K25="Milestone",$K25="Deadline"),$I25>=AR$4,$I25<AR$4+7),IF($K25="Deadline","◇","◆"),"") | AS25: =IF(AND(ISNUMBER($I25),OR($K25="Milestone",$K25="Deadline"),$I25>=AS$4,$I25<AS$4+7),IF($K25="Deadline","◇","◆"),"") | AT25: =IF(AND(ISNUMBER($I25),OR($K25="Milestone",$K25="Deadline"),$I25>=AT$4,$I25<AT$4+7),IF($K25="Deadline","◇","◆"),"") | AU25: =IF(AND(ISNUMBER($I25),OR($K25="Milestone",$K25="Deadline"),$I25>=AU$4,$I25<AU$4+7),IF($K25="Deadline","◇","◆"),"") | AV25: =IF(AND(ISNUMBER($I25),OR($K25="Milestone",$K25="Deadline"),$I25>=AV$4,$I25<AV$4+7),IF($K25="Deadline","◇","◆"),"") | ... CM25: =IF(AND(ISNUMBER($I25),OR($K25="Milestone",$K25="Deadline"),$I25>=CM$4,$I25<CM$4+7),IF($K25="Deadline","◇","◆"),"")
A26: T-256 | B26: Phase gates (SOW) | C26: Shared | G26: Gate 1 · Blueprint and working prototype sign-off | I26: 46418 | J26: =I26 -> 46418 | K26: Milestone | N26: MDLZ Product Lead; DP&E, Architecture, Data Governance, Business, Product | O26: =IF(AND(ISNUMBER(I26),ISNUMBER(J26)),J26-I26+1,"") -> 1 | AO26: =IF(AND(ISNUMBER($I26),OR($K26="Milestone",$K26="Deadline"),$I26>=AO$4,$I26<AO$4+7),IF($K26="Deadline","◇","◆"),"") | AP26: =IF(AND(ISNUMBER($I26),OR($K26="Milestone",$K26="Deadline"),$I26>=AP$4,$I26<AP$4+7),IF($K26="Deadline","◇","◆"),"") | AQ26: =IF(AND(ISNUMBER($I26),OR($K26="Milestone",$K26="Deadline"),$I26>=AQ$4,$I26<AQ$4+7),IF($K26="Deadline","◇","◆"),"") | AR26: =IF(AND(ISNUMBER($I26),OR($K26="Milestone",$K26="Deadline"),$I26>=AR$4,$I26<AR$4+7),IF($K26="Deadline","◇","◆"),"") | AS26: =IF(AND(ISNUMBER($I26),OR($K26="Milestone",$K26="Deadline"),$I26>=AS$4,$I26<AS$4+7),IF($K26="Deadline","◇","◆"),"") | AT26: =IF(AND(ISNUMBER($I26),OR($K26="Milestone",$K26="Deadline"),$I26>=AT$4,$I26<AT$4+7),IF($K26="Deadline","◇","◆"),"") | AU26: =IF(AND(ISNUMBER($I26),OR($K26="Milestone",$K26="Deadline"),$I26>=AU$4,$I26<AU$4+7),IF($K26="Deadline","◇","◆"),"") | AV26: =IF(AND(ISNUMBER($I26),OR($K26="Milestone",$K26="Deadline"),$I26>=AV$4,$I26<AV$4+7),IF($K26="Deadline","◇","◆"),"") | ... CM26: =IF(AND(ISNUMBER($I26),OR($K26="Milestone",$K26="Deadline"),$I26>=CM$4,$I26<CM$4+7),IF($K26="Deadline","◇","◆"),"")
A27: T-257 | B27: Phase gates (SOW) | C27: Shared | G27: Gate 2 · Migration complete | I27: 46477 | J27: =I27 -> 46477 | K27: Milestone | N27: MDLZ Product Lead, CDRB | O27: =IF(AND(ISNUMBER(I27),ISNUMBER(J27)),J27-I27+1,"") -> 1 | AO27: =IF(AND(ISNUMBER($I27),OR($K27="Milestone",$K27="Deadline"),$I27>=AO$4,$I27<AO$4+7),IF($K27="Deadline","◇","◆"),"") | AP27: =IF(AND(ISNUMBER($I27),OR($K27="Milestone",$K27="Deadline"),$I27>=AP$4,$I27<AP$4+7),IF($K27="Deadline","◇","◆"),"") | AQ27: =IF(AND(ISNUMBER($I27),OR($K27="Milestone",$K27="Deadline"),$I27>=AQ$4,$I27<AQ$4+7),IF($K27="Deadline","◇","◆"),"") | AR27: =IF(AND(ISNUMBER($I27),OR($K27="Milestone",$K27="Deadline"),$I27>=AR$4,$I27<AR$4+7),IF($K27="Deadline","◇","◆"),"") | AS27: =IF(AND(ISNUMBER($I27),OR($K27="Milestone",$K27="Deadline"),$I27>=AS$4,$I27<AS$4+7),IF($K27="Deadline","◇","◆"),"") | AT27: =IF(AND(ISNUMBER($I27),OR($K27="Milestone",$K27="Deadline"),$I27>=AT$4,$I27<AT$4+7),IF($K27="Deadline","◇","◆"),"") | AU27: =IF(AND(ISNUMBER($I27),OR($K27="Milestone",$K27="Deadline"),$I27>=AU$4,$I27<AU$4+7),IF($K27="Deadline","◇","◆"),"") | AV27: =IF(AND(ISNUMBER($I27),OR($K27="Milestone",$K27="Deadline"),$I27>=AV$4,$I27<AV$4+7),IF($K27="Deadline","◇","◆"),"") | ... CM27: =IF(AND(ISNUMBER($I27),OR($K27="Milestone",$K27="Deadline"),$I27>=CM$4,$I27<CM$4+7),IF($K27="Deadline","◇","◆"),"")
A28: T-258 | B28: Phase gates (SOW) | C28: Shared | G28: Gate 3 · User testing complete | I28: 46568 | J28: =I28 -> 46568 | K28: Milestone | N28: MDLZ Product Lead, CDRB | O28: =IF(AND(ISNUMBER(I28),ISNUMBER(J28)),J28-I28+1,"") -> 1 | AO28: =IF(AND(ISNUMBER($I28),OR($K28="Milestone",$K28="Deadline"),$I28>=AO$4,$I28<AO$4+7),IF($K28="Deadline","◇","◆"),"") | AP28: =IF(AND(ISNUMBER($I28),OR($K28="Milestone",$K28="Deadline"),$I28>=AP$4,$I28<AP$4+7),IF($K28="Deadline","◇","◆"),"") | AQ28: =IF(AND(ISNUMBER($I28),OR($K28="Milestone",$K28="Deadline"),$I28>=AQ$4,$I28<AQ$4+7),IF($K28="Deadline","◇","◆"),"") | AR28: =IF(AND(ISNUMBER($I28),OR($K28="Milestone",$K28="Deadline"),$I28>=AR$4,$I28<AR$4+7),IF($K28="Deadline","◇","◆"),"") | AS28: =IF(AND(ISNUMBER($I28),OR($K28="Milestone",$K28="Deadline"),$I28>=AS$4,$I28<AS$4+7),IF($K28="Deadline","◇","◆"),"") | AT28: =IF(AND(ISNUMBER($I28),OR($K28="Milestone",$K28="Deadline"),$I28>=AT$4,$I28<AT$4+7),IF($K28="Deadline","◇","◆"),"") | AU28: =IF(AND(ISNUMBER($I28),OR($K28="Milestone",$K28="Deadline"),$I28>=AU$4,$I28<AU$4+7),IF($K28="Deadline","◇","◆"),"") | AV28: =IF(AND(ISNUMBER($I28),OR($K28="Milestone",$K28="Deadline"),$I28>=AV$4,$I28<AV$4+7),IF($K28="Deadline","◇","◆"),"") | ... CM28: =IF(AND(ISNUMBER($I28),OR($K28="Milestone",$K28="Deadline"),$I28>=CM$4,$I28<CM$4+7),IF($K28="Deadline","◇","◆"),"")
A29: T-259 | B29: Phase gates (SOW) | C29: Shared | G29: Gate 4 · Integration test and UAT acceptance (go / no-go) | I29: 46630 | J29: =I29 -> 46630 | K29: Milestone | N29: MDLZ Product Lead, CDRB | O29: =IF(AND(ISNUMBER(I29),ISNUMBER(J29)),J29-I29+1,"") -> 1 | AO29: =IF(AND(ISNUMBER($I29),OR($K29="Milestone",$K29="Deadline"),$I29>=AO$4,$I29<AO$4+7),IF($K29="Deadline","◇","◆"),"") | AP29: =IF(AND(ISNUMBER($I29),OR($K29="Milestone",$K29="Deadline"),$I29>=AP$4,$I29<AP$4+7),IF($K29="Deadline","◇","◆"),"") | AQ29: =IF(AND(ISNUMBER($I29),OR($K29="Milestone",$K29="Deadline"),$I29>=AQ$4,$I29<AQ$4+7),IF($K29="Deadline","◇","◆"),"") | AR29: =IF(AND(ISNUMBER($I29),OR($K29="Milestone",$K29="Deadline"),$I29>=AR$4,$I29<AR$4+7),IF($K29="Deadline","◇","◆"),"") | AS29: =IF(AND(ISNUMBER($I29),OR($K29="Milestone",$K29="Deadline"),$I29>=AS$4,$I29<AS$4+7),IF($K29="Deadline","◇","◆"),"") | AT29: =IF(AND(ISNUMBER($I29),OR($K29="Milestone",$K29="Deadline"),$I29>=AT$4,$I29<AT$4+7),IF($K29="Deadline","◇","◆"),"") | AU29: =IF(AND(ISNUMBER($I29),OR($K29="Milestone",$K29="Deadline"),$I29>=AU$4,$I29<AU$4+7),IF($K29="Deadline","◇","◆"),"") | AV29: =IF(AND(ISNUMBER($I29),OR($K29="Milestone",$K29="Deadline"),$I29>=AV$4,$I29<AV$4+7),IF($K29="Deadline","◇","◆"),"") | ... CM29: =IF(AND(ISNUMBER($I29),OR($K29="Milestone",$K29="Deadline"),$I29>=CM$4,$I29<CM$4+7),IF($K29="Deadline","◇","◆"),"")
A30: T-260 | B30: Phase gates (SOW) | C30: Shared | G30: Gate 5 · Production readiness and go-live | I30: 46691 | J30: =I30 -> 46691 | K30: Milestone | N30: MDLZ Product team | O30: =IF(AND(ISNUMBER(I30),ISNUMBER(J30)),J30-I30+1,"") -> 1 | AO30: =IF(AND(ISNUMBER($I30),OR($K30="Milestone",$K30="Deadline"),$I30>=AO$4,$I30<AO$4+7),IF($K30="Deadline","◇","◆"),"") | AP30: =IF(AND(ISNUMBER($I30),OR($K30="Milestone",$K30="Deadline"),$I30>=AP$4,$I30<AP$4+7),IF($K30="Deadline","◇","◆"),"") | AQ30: =IF(AND(ISNUMBER($I30),OR($K30="Milestone",$K30="Deadline"),$I30>=AQ$4,$I30<AQ$4+7),IF($K30="Deadline","◇","◆"),"") | AR30: =IF(AND(ISNUMBER($I30),OR($K30="Milestone",$K30="Deadline"),$I30>=AR$4,$I30<AR$4+7),IF($K30="Deadline","◇","◆"),"") | AS30: =IF(AND(ISNUMBER($I30),OR($K30="Milestone",$K30="Deadline"),$I30>=AS$4,$I30<AS$4+7),IF($K30="Deadline","◇","◆"),"") | AT30: =IF(AND(ISNUMBER($I30),OR($K30="Milestone",$K30="Deadline"),$I30>=AT$4,$I30<AT$4+7),IF($K30="Deadline","◇","◆"),"") | AU30: =IF(AND(ISNUMBER($I30),OR($K30="Milestone",$K30="Deadline"),$I30>=AU$4,$I30<AU$4+7),IF($K30="Deadline","◇","◆"),"") | AV30: =IF(AND(ISNUMBER($I30),OR($K30="Milestone",$K30="Deadline"),$I30>=AV$4,$I30<AV$4+7),IF($K30="Deadline","◇","◆"),"") | ... CM30: =IF(AND(ISNUMBER($I30),OR($K30="Milestone",$K30="Deadline"),$I30>=CM$4,$I30<CM$4+7),IF($K30="Deadline","◇","◆"),"")
A31: T-261 | B31: Phase gates (SOW) | C31: Shared | G31: Gate 6 · Hypercare exit and transition to support | I31: 46752 | J31: =I31 -> 46752 | K31: Milestone | N31: MDLZ AMS and Product team leads | O31: =IF(AND(ISNUMBER(I31),ISNUMBER(J31)),J31-I31+1,"") -> 1 | AO31: =IF(AND(ISNUMBER($I31),OR($K31="Milestone",$K31="Deadline"),$I31>=AO$4,$I31<AO$4+7),IF($K31="Deadline","◇","◆"),"") | AP31: =IF(AND(ISNUMBER($I31),OR($K31="Milestone",$K31="Deadline"),$I31>=AP$4,$I31<AP$4+7),IF($K31="Deadline","◇","◆"),"") | AQ31: =IF(AND(ISNUMBER($I31),OR($K31="Milestone",$K31="Deadline"),$I31>=AQ$4,$I31<AQ$4+7),IF($K31="Deadline","◇","◆"),"") | AR31: =IF(AND(ISNUMBER($I31),OR($K31="Milestone",$K31="Deadline"),$I31>=AR$4,$I31<AR$4+7),IF($K31="Deadline","◇","◆"),"") | AS31: =IF(AND(ISNUMBER($I31),OR($K31="Milestone",$K31="Deadline"),$I31>=AS$4,$I31<AS$4+7),IF($K31="Deadline","◇","◆"),"") | AT31: =IF(AND(ISNUMBER($I31),OR($K31="Milestone",$K31="Deadline"),$I31>=AT$4,$I31<AT$4+7),IF($K31="Deadline","◇","◆"),"") | AU31: =IF(AND(ISNUMBER($I31),OR($K31="Milestone",$K31="Deadline"),$I31>=AU$4,$I31<AU$4+7),IF($K31="Deadline","◇","◆"),"") | AV31: =IF(AND(ISNUMBER($I31),OR($K31="Milestone",$K31="Deadline"),$I31>=AV$4,$I31<AV$4+7),IF($K31="Deadline","◇","◆"),"") | ... CM31: =IF(AND(ISNUMBER($I31),OR($K31="Milestone",$K31="Deadline"),$I31>=CM$4,$I31<CM$4+7),IF($K31="Deadline","◇","◆"),"")
A32: T-395 | B32: Phase gates (SOW) | C32: Shared | G32: Phase 3 complete, needed by | I32: 46507 | J32: =I32 -> 46507 | K32: Deadline | N32: Project team | O32: =IF(AND(ISNUMBER(I32),ISNUMBER(J32)),J32-I32+1,"") -> 1 | AO32: =IF(AND(ISNUMBER($I32),OR($K32="Milestone",$K32="Deadline"),$I32>=AO$4,$I32<AO$4+7),IF($K32="Deadline","◇","◆"),"") | AP32: =IF(AND(ISNUMBER($I32),OR($K32="Milestone",$K32="Deadline"),$I32>=AP$4,$I32<AP$4+7),IF($K32="Deadline","◇","◆"),"") | AQ32: =IF(AND(ISNUMBER($I32),OR($K32="Milestone",$K32="Deadline"),$I32>=AQ$4,$I32<AQ$4+7),IF($K32="Deadline","◇","◆"),"") | AR32: =IF(AND(ISNUMBER($I32),OR($K32="Milestone",$K32="Deadline"),$I32>=AR$4,$I32<AR$4+7),IF($K32="Deadline","◇","◆"),"") | AS32: =IF(AND(ISNUMBER($I32),OR($K32="Milestone",$K32="Deadline"),$I32>=AS$4,$I32<AS$4+7),IF($K32="Deadline","◇","◆"),"") | AT32: =IF(AND(ISNUMBER($I32),OR($K32="Milestone",$K32="Deadline"),$I32>=AT$4,$I32<AT$4+7),IF($K32="Deadline","◇","◆"),"") | AU32: =IF(AND(ISNUMBER($I32),OR($K32="Milestone",$K32="Deadline"),$I32>=AU$4,$I32<AU$4+7),IF($K32="Deadline","◇","◆"),"") | AV32: =IF(AND(ISNUMBER($I32),OR($K32="Milestone",$K32="Deadline"),$I32>=AV$4,$I32<AV$4+7),IF($K32="Deadline","◇","◆"),"") | ... CM32: =IF(AND(ISNUMBER($I32),OR($K32="Milestone",$K32="Deadline"),$I32>=CM$4,$I32<CM$4+7),IF($K32="Deadline","◇","◆"),"")
A33: T-10 | B33: Foundations | C33: Phase 1 | F33: Phase 1 · Foundations | G33: Audit design | H33: 7 | I33: 46335 | J33: =IF(AND(ISNUMBER(I33),ISNUMBER(H33)),I33+H33-1,"") -> 46341 | K33: Task | O33: =IF(AND(ISNUMBER(I33),ISNUMBER(J33)),J33-I33+1,"") -> 7 | U33: x | V33: x | X33: x | Z33: x | AO33: =IF(AND(ISNUMBER($I33),OR($K33="Milestone",$K33="Deadline"),$I33>=AO$4,$I33<AO$4+7),IF($K33="Deadline","◇","◆"),"") | AP33: =IF(AND(ISNUMBER($I33),OR($K33="Milestone",$K33="Deadline"),$I33>=AP$4,$I33<AP$4+7),IF($K33="Deadline","◇","◆"),"") | AQ33: =IF(AND(ISNUMBER($I33),OR($K33="Milestone",$K33="Deadline"),$I33>=AQ$4,$I33<AQ$4+7),IF($K33="Deadline","◇","◆"),"") | AR33: =IF(AND(ISNUMBER($I33),OR($K33="Milestone",$K33="Deadline"),$I33>=AR$4,$I33<AR$4+7),IF($K33="Deadline","◇","◆"),"") | AS33: =IF(AND(ISNUMBER($I33),OR($K33="Milestone",$K33="Deadline"),$I33>=AS$4,$I33<AS$4+7),IF($K33="Deadline","◇","◆"),"") | AT33: =IF(AND(ISNUMBER($I33),OR($K33="Milestone",$K33="Deadline"),$I33>=AT$4,$I33<AT$4+7),IF($K33="Deadline","◇","◆"),"") | AU33: =IF(AND(ISNUMBER($I33),OR($K33="Milestone",$K33="Deadline"),$I33>=AU$4,$I33<AU$4+7),IF($K33="Deadline","◇","◆"),"") | AV33: =IF(AND(ISNUMBER($I33),OR($K33="Milestone",$K33="Deadline"),$I33>=AV$4,$I33<AV$4+7),IF($K33="Deadline","◇","◆"),"") | ... CM33: =IF(AND(ISNUMBER($I33),OR($K33="Milestone",$K33="Deadline"),$I33>=CM$4,$I33<CM$4+7),IF($K33="Deadline","◇","◆"),"")
A34: T-11 | B34: Foundations | C34: Phase 1 | F34: Phase 1 · Foundations | G34: Log design | H34: 7 | I34: =MAX($C$2,J33+1,J42+1) -> 46349 | J34: =IF(AND(ISNUMBER(I34),ISNUMBER(H34)),I34+H34-1,"") -> 46355 | K34: Task | L34: T-10 | M34: T-19 | O34: =IF(AND(ISNUMBER(I34),ISNUMBER(J34)),J34-I34+1,"") -> 7 | U34: x | V34: x | X34: x | AE34: x | AO34: =IF(AND(ISNUMBER($I34),OR($K34="Milestone",$K34="Deadline"),$I34>=AO$4,$I34<AO$4+7),IF($K34="Deadline","◇","◆"),"") | AP34: =IF(AND(ISNUMBER($I34),OR($K34="Milestone",$K34="Deadline"),$I34>=AP$4,$I34<AP$4+7),IF($K34="Deadline","◇","◆"),"") | AQ34: =IF(AND(ISNUMBER($I34),OR($K34="Milestone",$K34="Deadline"),$I34>=AQ$4,$I34<AQ$4+7),IF($K34="Deadline","◇","◆"),"") | AR34: =IF(AND(ISNUMBER($I34),OR($K34="Milestone",$K34="Deadline"),$I34>=AR$4,$I34<AR$4+7),IF($K34="Deadline","◇","◆"),"") | AS34: =IF(AND(ISNUMBER($I34),OR($K34="Milestone",$K34="Deadline"),$I34>=AS$4,$I34<AS$4+7),IF($K34="Deadline","◇","◆"),"") | AT34: =IF(AND(ISNUMBER($I34),OR($K34="Milestone",$K34="Deadline"),$I34>=AT$4,$I34<AT$4+7),IF($K34="Deadline","◇","◆"),"") | AU34: =IF(AND(ISNUMBER($I34),OR($K34="Milestone",$K34="Deadline"),$I34>=AU$4,$I34<AU$4+7),IF($K34="Deadline","◇","◆"),"") | AV34: =IF(AND(ISNUMBER($I34),OR($K34="Milestone",$K34="Deadline"),$I34>=AV$4,$I34<AV$4+7),IF($K34="Deadline","◇","◆"),"") | ... CM34: =IF(AND(ISNUMBER($I34),OR($K34="Milestone",$K34="Deadline"),$I34>=CM$4,$I34<CM$4+7),IF($K34="Deadline","◇","◆"),"")
A35: T-12 | B35: Foundations | C35: Phase 1 | F35: Phase 1 · Foundations | G35: Data quality checks design | H35: 14 | I35: =MAX(DATE(2026,11,9),J78+1) -> 46335 | J35: =IF(AND(ISNUMBER(I35),ISNUMBER(H35)),I35+H35-1,"") -> 46348 | K35: Task | M35: T-244 | O35: =IF(AND(ISNUMBER(I35),ISNUMBER(J35)),J35-I35+1,"") -> 14 | U35: x | W35: x | X35: x | AD35: x | AO35: =IF(AND(ISNUMBER($I35),OR($K35="Milestone",$K35="Deadline"),$I35>=AO$4,$I35<AO$4+7),IF($K35="Deadline","◇","◆"),"") | AP35: =IF(AND(ISNUMBER($I35),OR($K35="Milestone",$K35="Deadline"),$I35>=AP$4,$I35<AP$4+7),IF($K35="Deadline","◇","◆"),"") | AQ35: =IF(AND(ISNUMBER($I35),OR($K35="Milestone",$K35="Deadline"),$I35>=AQ$4,$I35<AQ$4+7),IF($K35="Deadline","◇","◆"),"") | AR35: =IF(AND(ISNUMBER($I35),OR($K35="Milestone",$K35="Deadline"),$I35>=AR$4,$I35<AR$4+7),IF($K35="Deadline","◇","◆"),"") | AS35: =IF(AND(ISNUMBER($I35),OR($K35="Milestone",$K35="Deadline"),$I35>=AS$4,$I35<AS$4+7),IF($K35="Deadline","◇","◆"),"") | AT35: =IF(AND(ISNUMBER($I35),OR($K35="Milestone",$K35="Deadline"),$I35>=AT$4,$I35<AT$4+7),IF($K35="Deadline","◇","◆"),"") | AU35: =IF(AND(ISNUMBER($I35),OR($K35="Milestone",$K35="Deadline"),$I35>=AU$4,$I35<AU$4+7),IF($K35="Deadline","◇","◆"),"") | AV35: =IF(AND(ISNUMBER($I35),OR($K35="Milestone",$K35="Deadline"),$I35>=AV$4,$I35<AV$4+7),IF($K35="Deadline","◇","◆"),"") | ... CM35: =IF(AND(ISNUMBER($I35),OR($K35="Milestone",$K35="Deadline"),$I35>=CM$4,$I35<CM$4+7),IF($K35="Deadline","◇","◆"),"")
A36: T-13 | B36: Foundations | C36: Phase 1 | F36: Phase 1 · Foundations | G36: Custom tags design | H36: 7 | I36: =MAX($C$2,J34+1) -> 46356 | J36: =IF(AND(ISNUMBER(I36),ISNUMBER(H36)),I36+H36-1,"") -> 46362 | K36: Task | L36: T-11 | O36: =IF(AND(ISNUMBER(I36),ISNUMBER(J36)),J36-I36+1,"") -> 7 | U36: x | X36: x | AH36: x | AO36: =IF(AND(ISNUMBER($I36),OR($K36="Milestone",$K36="Deadline"),$I36>=AO$4,$I36<AO$4+7),IF($K36="Deadline","◇","◆"),"") | AP36: =IF(AND(ISNUMBER($I36),OR($K36="Milestone",$K36="Deadline"),$I36>=AP$4,$I36<AP$4+7),IF($K36="Deadline","◇","◆"),"") | AQ36: =IF(AND(ISNUMBER($I36),OR($K36="Milestone",$K36="Deadline"),$I36>=AQ$4,$I36<AQ$4+7),IF($K36="Deadline","◇","◆"),"") | AR36: =IF(AND(ISNUMBER($I36),OR($K36="Milestone",$K36="Deadline"),$I36>=AR$4,$I36<AR$4+7),IF($K36="Deadline","◇","◆"),"") | AS36: =IF(AND(ISNUMBER($I36),OR($K36="Milestone",$K36="Deadline"),$I36>=AS$4,$I36<AS$4+7),IF($K36="Deadline","◇","◆"),"") | AT36: =IF(AND(ISNUMBER($I36),OR($K36="Milestone",$K36="Deadline"),$I36>=AT$4,$I36<AT$4+7),IF($K36="Deadline","◇","◆"),"") | AU36: =IF(AND(ISNUMBER($I36),OR($K36="Milestone",$K36="Deadline"),$I36>=AU$4,$I36<AU$4+7),IF($K36="Deadline","◇","◆"),"") | AV36: =IF(AND(ISNUMBER($I36),OR($K36="Milestone",$K36="Deadline"),$I36>=AV$4,$I36<AV$4+7),IF($K36="Deadline","◇","◆"),"") | ... CM36: =IF(AND(ISNUMBER($I36),OR($K36="Milestone",$K36="Deadline"),$I36>=CM$4,$I36<CM$4+7),IF($K36="Deadline","◇","◆"),"")
A37: T-14 | B37: Foundations | C37: Phase 1 | F37: Phase 1 · Foundations | G37: Notebook template | H37: 14 | I37: =MAX($C$2,J35+1,J199+1) -> 46349 | J37: =IF(AND(ISNUMBER(I37),ISNUMBER(H37)),I37+H37-1,"") -> 46362 | K37: Task | L37: T-12 | M37: T-275 | O37: =IF(AND(ISNUMBER(I37),ISNUMBER(J37)),J37-I37+1,"") -> 14 | U37: x | V37: x | W37: x | X37: x | AI37: x | AO37: =IF(AND(ISNUMBER($I37),OR($K37="Milestone",$K37="Deadline"),$I37>=AO$4,$I37<AO$4+7),IF($K37="Deadline","◇","◆"),"") | AP37: =IF(AND(ISNUMBER($I37),OR($K37="Milestone",$K37="Deadline"),$I37>=AP$4,$I37<AP$4+7),IF($K37="Deadline","◇","◆"),"") | AQ37: =IF(AND(ISNUMBER($I37),OR($K37="Milestone",$K37="Deadline"),$I37>=AQ$4,$I37<AQ$4+7),IF($K37="Deadline","◇","◆"),"") | AR37: =IF(AND(ISNUMBER($I37),OR($K37="Milestone",$K37="Deadline"),$I37>=AR$4,$I37<AR$4+7),IF($K37="Deadline","◇","◆"),"") | AS37: =IF(AND(ISNUMBER($I37),OR($K37="Milestone",$K37="Deadline"),$I37>=AS$4,$I37<AS$4+7),IF($K37="Deadline","◇","◆"),"") | AT37: =IF(AND(ISNUMBER($I37),OR($K37="Milestone",$K37="Deadline"),$I37>=AT$4,$I37<AT$4+7),IF($K37="Deadline","◇","◆"),"") | AU37: =IF(AND(ISNUMBER($I37),OR($K37="Milestone",$K37="Deadline"),$I37>=AU$4,$I37<AU$4+7),IF($K37="Deadline","◇","◆"),"") | AV37: =IF(AND(ISNUMBER($I37),OR($K37="Milestone",$K37="Deadline"),$I37>=AV$4,$I37<AV$4+7),IF($K37="Deadline","◇","◆"),"") | ... CM37: =IF(AND(ISNUMBER($I37),OR($K37="Milestone",$K37="Deadline"),$I37>=CM$4,$I37<CM$4+7),IF($K37="Deadline","◇","◆"),"")
A38: T-15 | B38: Foundations | C38: Phase 1 | F38: Phase 1 · Foundations | G38: Test dataset ZZ design | H38: 14 | I38: =MAX($C$2,J36+1,J215+1) -> 46363 | J38: =IF(AND(ISNUMBER(I38),ISNUMBER(H38)),I38+H38-1,"") -> 46376 | K38: Task | L38: T-13 | M38: T-276 | O38: =IF(AND(ISNUMBER(I38),ISNUMBER(J38)),J38-I38+1,"") -> 14 | U38: x | V38: x | W38: x | X38: x | Z38: x | AO38: =IF(AND(ISNUMBER($I38),OR($K38="Milestone",$K38="Deadline"),$I38>=AO$4,$I38<AO$4+7),IF($K38="Deadline","◇","◆"),"") | AP38: =IF(AND(ISNUMBER($I38),OR($K38="Milestone",$K38="Deadline"),$I38>=AP$4,$I38<AP$4+7),IF($K38="Deadline","◇","◆"),"") | AQ38: =IF(AND(ISNUMBER($I38),OR($K38="Milestone",$K38="Deadline"),$I38>=AQ$4,$I38<AQ$4+7),IF($K38="Deadline","◇","◆"),"") | AR38: =IF(AND(ISNUMBER($I38),OR($K38="Milestone",$K38="Deadline"),$I38>=AR$4,$I38<AR$4+7),IF($K38="Deadline","◇","◆"),"") | AS38: =IF(AND(ISNUMBER($I38),OR($K38="Milestone",$K38="Deadline"),$I38>=AS$4,$I38<AS$4+7),IF($K38="Deadline","◇","◆"),"") | AT38: =IF(AND(ISNUMBER($I38),OR($K38="Milestone",$K38="Deadline"),$I38>=AT$4,$I38<AT$4+7),IF($K38="Deadline","◇","◆"),"") | AU38: =IF(AND(ISNUMBER($I38),OR($K38="Milestone",$K38="Deadline"),$I38>=AU$4,$I38<AU$4+7),IF($K38="Deadline","◇","◆"),"") | AV38: =IF(AND(ISNUMBER($I38),OR($K38="Milestone",$K38="Deadline"),$I38>=AV$4,$I38<AV$4+7),IF($K38="Deadline","◇","◆"),"") | ... CM38: =IF(AND(ISNUMBER($I38),OR($K38="Milestone",$K38="Deadline"),$I38>=CM$4,$I38<CM$4+7),IF($K38="Deadline","◇","◆"),"")
A39: T-16 | B39: Foundations | C39: Phase 1 | F39: Phase 1 · Foundations | G39: Incremental load design | H39: 7 | I39: =MAX($C$2,J37+1,J37+1) -> 46363 | J39: =IF(AND(ISNUMBER(I39),ISNUMBER(H39)),I39+H39-1,"") -> 46369 | K39: Task | L39: T-14 | M39: T-14 | O39: =IF(AND(ISNUMBER(I39),ISNUMBER(J39)),J39-I39+1,"") -> 7 | U39: x | V39: x | X39: x | AI39: x | AO39: =IF(AND(ISNUMBER($I39),OR($K39="Milestone",$K39="Deadline"),$I39>=AO$4,$I39<AO$4+7),IF($K39="Deadline","◇","◆"),"") | AP39: =IF(AND(ISNUMBER($I39),OR($K39="Milestone",$K39="Deadline"),$I39>=AP$4,$I39<AP$4+7),IF($K39="Deadline","◇","◆"),"") | AQ39: =IF(AND(ISNUMBER($I39),OR($K39="Milestone",$K39="Deadline"),$I39>=AQ$4,$I39<AQ$4+7),IF($K39="Deadline","◇","◆"),"") | AR39: =IF(AND(ISNUMBER($I39),OR($K39="Milestone",$K39="Deadline"),$I39>=AR$4,$I39<AR$4+7),IF($K39="Deadline","◇","◆"),"") | AS39: =IF(AND(ISNUMBER($I39),OR($K39="Milestone",$K39="Deadline"),$I39>=AS$4,$I39<AS$4+7),IF($K39="Deadline","◇","◆"),"") | AT39: =IF(AND(ISNUMBER($I39),OR($K39="Milestone",$K39="Deadline"),$I39>=AT$4,$I39<AT$4+7),IF($K39="Deadline","◇","◆"),"") | AU39: =IF(AND(ISNUMBER($I39),OR($K39="Milestone",$K39="Deadline"),$I39>=AU$4,$I39<AU$4+7),IF($K39="Deadline","◇","◆"),"") | AV39: =IF(AND(ISNUMBER($I39),OR($K39="Milestone",$K39="Deadline"),$I39>=AV$4,$I39<AV$4+7),IF($K39="Deadline","◇","◆"),"") | ... CM39: =IF(AND(ISNUMBER($I39),OR($K39="Milestone",$K39="Deadline"),$I39>=CM$4,$I39<CM$4+7),IF($K39="Deadline","◇","◆"),"")
A40: T-17 | B40: Foundations | C40: Phase 1 | F40: Phase 1 · Foundations | G40: Sensitive data classification (F-17) | H40: 7 | I40: =MAX($C$2,J39+1,J189+1) -> 46370 | J40: =IF(AND(ISNUMBER(I40),ISNUMBER(H40)),I40+H40-1,"") -> 46376 | K40: Task | L40: T-16 | M40: T-235 | O40: =IF(AND(ISNUMBER(I40),ISNUMBER(J40)),J40-I40+1,"") -> 7 | U40: x | W40: x | X40: x | AH40: x | AO40: =IF(AND(ISNUMBER($I40),OR($K40="Milestone",$K40="Deadline"),$I40>=AO$4,$I40<AO$4+7),IF($K40="Deadline","◇","◆"),"") | AP40: =IF(AND(ISNUMBER($I40),OR($K40="Milestone",$K40="Deadline"),$I40>=AP$4,$I40<AP$4+7),IF($K40="Deadline","◇","◆"),"") | AQ40: =IF(AND(ISNUMBER($I40),OR($K40="Milestone",$K40="Deadline"),$I40>=AQ$4,$I40<AQ$4+7),IF($K40="Deadline","◇","◆"),"") | AR40: =IF(AND(ISNUMBER($I40),OR($K40="Milestone",$K40="Deadline"),$I40>=AR$4,$I40<AR$4+7),IF($K40="Deadline","◇","◆"),"") | AS40: =IF(AND(ISNUMBER($I40),OR($K40="Milestone",$K40="Deadline"),$I40>=AS$4,$I40<AS$4+7),IF($K40="Deadline","◇","◆"),"") | AT40: =IF(AND(ISNUMBER($I40),OR($K40="Milestone",$K40="Deadline"),$I40>=AT$4,$I40<AT$4+7),IF($K40="Deadline","◇","◆"),"") | AU40: =IF(AND(ISNUMBER($I40),OR($K40="Milestone",$K40="Deadline"),$I40>=AU$4,$I40<AU$4+7),IF($K40="Deadline","◇","◆"),"") | AV40: =IF(AND(ISNUMBER($I40),OR($K40="Milestone",$K40="Deadline"),$I40>=AV$4,$I40<AV$4+7),IF($K40="Deadline","◇","◆"),"") | ... CM40: =IF(AND(ISNUMBER($I40),OR($K40="Milestone",$K40="Deadline"),$I40>=CM$4,$I40<CM$4+7),IF($K40="Deadline","◇","◆"),"")
...

Sheet Engagement
A1: Parallel tasks per resource per week
A2: Highest number of tasks the resource has on any single day of the week (tasks marked x).
C3: =Timeline!AO3 -> paź yy | D3: =Timeline!AP3 | E3: =Timeline!AQ3 | F3: =Timeline!AR3 -> lis yy | G3: =Timeline!AS3 | H3: =Timeline!AT3 | I3: =Timeline!AU3 | J3: =Timeline!AV3 | ... BA3: =Timeline!CM3
A4: Resource | B4: Role | C4: =Timeline!AO4 -> 46307 | D4: =Timeline!AP4 -> 46314 | E4: =Timeline!AQ4 -> 46321 | F4: =Timeline!AR4 -> 46328 | G4: =Timeline!AS4 -> 46335 | H4: =Timeline!AT4 -> 46342 | I4: =Timeline!AU4 -> 46349 | J4: =Timeline!AV4 -> 46356 | ... BA4: =Timeline!CM4 -> 46657
